<robot name="spiderbot">
    <link name="SpiderBody">
        <visual>
            <origin xyz="0 0 0.025"/>
            <geometry>
                <box size="0.095 0.093 0.089"/>
            </geometry>
            <material name = "Blue">
                <color rgba="0 0.79 1.0 1.0"/>               
            </material>   
        </visual>
        <collision>
            <origin xyz="0 0 0.035"/>
            <geometry>
                <box size="0.095 0.093 0.089"/>
            </geometry>
        </collision>
        <inertial>
            <mass value="25"/>
            <inertia ixx="1.0" ixy="0.0" ixz="0.0" iyy="1.0" iyz="0.0" izz="1.0"/>
        </inertial>
    </link>


    <!-- Front Left Leg  -->
    <link name="FL0">
        <visual>
            <origin xyz="0 0.021567 0" rpy="0.0 1.571 0"/>
            <geometry>
                <box size="0.03683 0.043134 0.0127"/>
            </geometry>
            <material name = "Orange">
                <color rgba="1.0 0.54 0.0 1.0"/>               
            </material>   
        </visual>
        <collision>
            <geometry>
                <box size="0.03683 0.043134 0.0127"/>
            </geometry>
        </collision>
        <inertial>
            <mass value="1"/>
            <inertia ixx="1.0" ixy="0.0" ixz="0.0" iyy="1.0" iyz="0.0" izz="1.0"/>
        </inertial>
    </link>
    <joint name="FLJ0" type="revolute">
        <axis xyz="0 0 -1"/>
        <parent link="SpiderBody"/>
        <child link="FL0"/>
        <origin rpy="0.0 0 3.1415" xyz="-0.034317 -0.050021 0"/>
        <limit effort="100" velocity="100" lower="-1.571" upper="1.571"/>
        <joint_properties damping="0.0" friction="0.0"/>
    </joint>

    <link name="FL1">
        <visual>
            <origin xyz="0 0.0325 0" rpy="0.0 1.571 0.0"/>
            <geometry>
                <box size="0.0127 0.06541 0.0381"/>
            </geometry>
            <material name = "Orange">
                <color rgba="1.0 0.54 0.0 1.0"/>               
            </material>   
        </visual>
        <collision>
            <origin xyz="0 0.0325 0" rpy="0.0 1.571 0.0"/>
            <geometry>
                <box size="0.0127 0.06541 0.0381"/>
            </geometry>
        </collision>
        <inertial>
            <mass value="1"/>
            <inertia ixx="1.0" ixy="0.0" ixz="0.0" iyy="1.0" iyz="0.0" izz="1.0"/>
        </inertial>
    </link>
    <joint name="FLJ1" type="revolute">
        <axis xyz="1 0 0"/>
        <parent link="FL0"/>
        <child link="FL1"/>
        <origin rpy="0 0 0" xyz="0 0.028395 0"/>
        <limit effort="100" velocity="100" lower="-1.571" upper="1.571"/>
        <joint_properties damping="0.0" friction="0.0"/>
    </joint>

    <link name="FL2">
        <visual>
            <origin xyz="0 0.052 0" rpy="1.571 0 0"/>
            <geometry>
                <cylinder radius=".008" length="0.104"/>
            </geometry>
            <material name = "Orange">
                <color rgba="1.0 0.54 0.0 1.0"/>               
            </material>   
        </visual>
        <collision>
            <origin xyz="0 0.052 0" rpy="1.571 0 0"/>
            <geometry>
                <cylinder radius=".008" length="0.104"/>
            </geometry>
        </collision>
        <inertial>
            <mass value="1"/>
            <inertia ixx="1.0" ixy="0.0" ixz="0.0" iyy="1.0" iyz="0.0" izz="1.0"/>
        </inertial>
    </link>
    <joint name="FLJ2" type="revolute">
        <axis xyz="1 0 0"/>
        <parent link="FL1"/>
        <child link="FL2"/>
        <origin rpy="0 0 0" xyz="0 0.06 0"/>
        <limit effort="100" velocity="100" lower="-1.571" upper="-0.4"/>
        <joint_properties damping="0.0" friction="0.0"/>
    </joint>

    <link name="FLE">
        <inertial>
            <origin xyz="0.0 0.0 0.0" rpy="0.0 0.0 0.0"/>
            <mass value="0.5"/>
            <inertia ixx="1.0" ixy="0.0" ixz="0.0" iyy="1.0" iyz="0.0" izz="1.0"/>
        </inertial>
        <visual name="FLRubberEnd">
            <origin xyz="0.0 0.0 0.0" rpy="0.0 0.0 0.0"/>
            <geometry>
                <sphere radius="0.008"/>
            </geometry>
            <material name="White">
                <color rgba="1.0 1.0 1.0 1.0"/>
            </material>
        </visual>
        <collision>
            <origin xyz="0.0 0.0 0.0" rpy="0.0 0.0 0.0"/>
            <geometry>
                <sphere radius="0.008"/>
            </geometry>
        </collision>
    </link>
    <joint name="FLEJ" type="fixed">
        <origin xyz="0.0 0.104 0.0" rpy="0.0 0.0 0.0"/>
        <parent link="FL2"/>
        <child link="FLE"/>
    </joint>


    <!-- Front Right Leg  -->
    <link name="FR0">
        <visual>
            <origin xyz="0 0.021567 0" rpy="0.0 1.571 0"/>
            <geometry>
                <box size="0.03683 0.043134 0.0127"/>
            </geometry>
            <material name = "Green">
                <color rgba="0 1 0.0 1.0"/>               
            </material>   
        </visual>
        <collision>
            <origin xyz="0 0.021567 0" rpy="0.0 1.571 0"/>
            <geometry>
                <box size="0.03683 0.043134 0.0127"/>
            </geometry>
        </collision>
        <inertial>
            <mass value="1"/>
            <inertia ixx="1.0" ixy="0.0" ixz="0.0" iyy="1.0" iyz="0.0" izz="1.0"/>
        </inertial>
    </link>
    <joint name="FRJ0" type="revolute">
        <axis xyz="0 0 1"/>
        <parent link="SpiderBody"/>
        <child link="FR0"/>
        <origin rpy="0.0 0 0" xyz="-0.034317 0.050021 0"/>
        <limit effort="100" velocity="100" lower="-1.571" upper="1.571"/>
        <joint_properties damping="0.0" friction="0.0"/>
    </joint>

    <link name="FR1">
        <visual>
            <origin xyz="0 0.0325 0" rpy="0.0 1.571 0.0"/>
            <geometry>
                <box size="0.0127 0.06541 0.0381"/>
            </geometry>
            <material name = "Green">
                <color rgba="0 1 0.0 1.0"/>               
            </material>  
        </visual>
        <collision>
            <origin xyz="0 0.0325 0" rpy="0.0 1.571 0.0"/>
            <geometry>
                <box size="0.0127 0.06541 0.0381"/>
            </geometry>
        </collision>
        <inertial>
            <mass value="1"/>
            <inertia ixx="1.0" ixy="0.0" ixz="0.0" iyy="1.0" iyz="0.0" izz="1.0"/>
        </inertial>
    </link>
    <joint name="FRJ1" type="revolute">
        <axis xyz="1 0 0"/>
        <parent link="FR0"/>
        <child link="FR1"/>
        <origin rpy="0 0 0" xyz="0 0.028395 0"/>
        <limit effort="100" velocity="100" lower="-1.571" upper="1.571"/>
        <joint_properties damping="0.0" friction="0.0"/>
    </joint>

    <link name="FR2">
        <visual>
            <origin xyz="0 0.052 0" rpy="1.571 0 0"/>
            <geometry>
                <cylinder radius=".008" length="0.104"/>
            </geometry>
            <material name = "Green">
                <color rgba="0 1 0.0 1.0"/>               
            </material>   
        </visual>
        <collision>
            <origin xyz="0 0.052 0" rpy="1.571 0 0"/>
            <geometry>
                <cylinder radius=".008" length="0.104"/>
            </geometry>
        </collision>
        <inertial>
            <mass value="1"/>
            <inertia ixx="1.0" ixy="0.0" ixz="0.0" iyy="1.0" iyz="0.0" izz="1.0"/>
        </inertial>
    </link>
    <joint name="FRJ2" type="revolute">
        <axis xyz="1 0 0"/>
        <parent link="FR1"/>
        <child link="FR2"/>
        <origin rpy="0 0 0" xyz="0 0.06 0"/>
        <limit effort="100" velocity="100" lower="-1.571" upper="-0.4"/>
        <joint_properties damping="0.0" friction="0.0"/>
    </joint>

        <link name="FRE">
        <inertial>
            <origin xyz="0.0 0.0 0.0" rpy="0.0 0.0 0.0"/>
            <mass value="0.5"/>
            <inertia ixx="1.0" ixy="0.0" ixz="0.0" iyy="1.0" iyz="0.0" izz="1.0"/>
        </inertial>
        <visual name="FRRubberEnd">
            <origin xyz="0.0 0.0 0.0" rpy="0.0 0.0 0.0"/>
            <geometry>
                <sphere radius="0.008"/>
            </geometry>
            <material name="White">
                <color rgba="1.0 1.0 1.0 1.0"/>
            </material>
        </visual>
        <collision>
            <origin xyz="0.0 0.0 0.0" rpy="0.0 0.0 0.0"/>
            <geometry>
                <sphere radius="0.008"/>
            </geometry>
        </collision>
    </link>
    <joint name="FREJ" type="fixed">
        <origin xyz="0.0 0.104 0.0" rpy="0.0 0.0 0.0"/>
        <parent link="FR2"/>
        <child link="FRE"/>
    </joint>

    <!-- Back Left Leg  -->
    <link name="BL0">
        <visual>
            <origin xyz="0 0.021567 0" rpy="0.0 1.571 0"/>
            <geometry>
                <box size="0.03683 0.043134 0.0127"/>
            </geometry>
            <material name = "Gold">
                <color rgba="1 1 0.0 1.0"/>               
            </material>   
        </visual>
        <collision>
            <origin xyz="0 0.021567 0" rpy="0.0 1.571 0"/>
            <geometry>
                <box size="0.03683 0.043134 0.0127"/>
            </geometry>
        </collision>
        <inertial>
            <mass value="1"/>
            <inertia ixx="1.0" ixy="0.0" ixz="0.0" iyy="1.0" iyz="0.0" izz="1.0"/>
        </inertial>
    </link>
    <joint name="BLJ0" type="revolute">
        <axis xyz="0 0 1"/>
        <parent link="SpiderBody"/>
        <child link="BL0"/>
        <origin rpy="0.0 0 3.1415" xyz="0.034317 -0.050021 0"/>
        <limit effort="100" velocity="100" lower="-1.571" upper="1.571"/>
        <joint_properties damping="0.0" friction="0.0"/>
    </joint>

    <link name="BL1">
        <visual>
            <origin xyz="0 0.0325 0" rpy="0.0 1.571 0.0"/>
            <geometry>
                <box size="0.0127 0.06541 0.0381"/>
            </geometry>
            <material name = "Gold">
                <color rgba="1 1 0.0 1.0"/>               
            </material>    
        </visual>
        <collision>
            <origin xyz="0 0.0325 0" rpy="0.0 1.571 0.0"/>
            <geometry>
                <box size="0.0127 0.06541 0.0381"/>
            </geometry>
        </collision>
        <inertial>
            <mass value="1"/>
            <inertia ixx="1.0" ixy="0.0" ixz="0.0" iyy="1.0" iyz="0.0" izz="1.0"/>
        </inertial>
    </link>
    <joint name="BLJ1" type="revolute">
        <axis xyz="1 0 0"/>
        <parent link="BL0"/>
        <child link="BL1"/>
        <origin rpy="0 0 0" xyz="0 0.028395 0"/>
        <limit effort="100" velocity="100" lower="-1.571" upper="1.571"/>
        <joint_properties damping="0.0" friction="0.0"/>
    </joint>

    <link name="BL2">
        <visual>
            <origin xyz="0 0.052 0" rpy="1.571 0 0"/>
            <geometry>
                <cylinder radius=".008" length="0.104"/>
            </geometry>
            <material name = "Gold">
                <color rgba="1 1 0.0 1.0"/>               
            </material>     
        </visual>
        <collision>
            <origin xyz="0 0.052 0" rpy="1.571 0 0"/>
            <geometry>
                <cylinder radius=".008" length="0.104"/>
            </geometry>
        </collision>
        <inertial>
            <mass value="1"/>
            <inertia ixx="1.0" ixy="0.0" ixz="0.0" iyy="1.0" iyz="0.0" izz="1.0"/>
        </inertial>
    </link>
    <joint name="BLJ2" type="revolute">
        <axis xyz="1 0 0"/>
        <parent link="BL1"/>
        <child link="BL2"/>
        <origin rpy="0 0 0" xyz="0 0.06 0"/>
        <limit effort="100" velocity="100" lower="-1.571" upper="-0.4"/>
        <joint_properties damping="0.0" friction="0.0"/>
    </joint>

        <link name="BLE">
        <inertial>
            <origin xyz="0.0 0.0 0.0" rpy="0.0 0.0 0.0"/>
            <mass value="0.5"/>
            <inertia ixx="1.0" ixy="0.0" ixz="0.0" iyy="1.0" iyz="0.0" izz="1.0"/>
        </inertial>
        <visual name="BLRubberEnd">
            <origin xyz="0.0 0.0 0.0" rpy="0.0 0.0 0.0"/>
            <geometry>
                <sphere radius="0.008"/>
            </geometry>
            <material name="White">
                <color rgba="1.0 1.0 1.0 1.0"/>
            </material>
        </visual>
        <collision>
            <origin xyz="0.0 0.0 0.0" rpy="0.0 0.0 0.0"/>
            <geometry>
                <sphere radius="0.008"/>
            </geometry>
        </collision>
    </link>
    <joint name="BLEJ" type="fixed">
        <origin xyz="0.0 0.104 0.0" rpy="0.0 0.0 0.0"/>
        <parent link="BL2"/>
        <child link="BLE"/>
    </joint>

    <!-- Back Right Leg  -->
    <link name="BR0">
        <visual>
            <origin xyz="0 0.021567 0" rpy="0.0 1.571 0"/>
            <geometry>
                <box size="0.03683 0.043134 0.0127"/>
            </geometry>
            <material name = "Purple">
                <color rgba="0.522 0 1 1.0"/>               
            </material>   
        </visual>
        <collision>
            <origin xyz="0 0.021567 0" rpy="0.0 1.571 0"/>
            <geometry>
                <box size="0.03683 0.043134 0.0127"/>
            </geometry>
        </collision>
        <inertial>
            <mass value="1"/>
            <inertia ixx="1.0" ixy="0.0" ixz="0.0" iyy="1.0" iyz="0.0" izz="1.0"/>
        </inertial>
    </link>
    <joint name="BRJ0" type="revolute">
        <axis xyz="0 0 -1"/>
        <parent link="SpiderBody"/>
        <child link="BR0"/>
        <origin rpy="0.0 0 0" xyz="0.034317 0.050021 0"/>
        <limit effort="100" velocity="100" lower="-1.571" upper="1.571"/>
        <joint_properties damping="0.0" friction="0.0"/>
    </joint>

    <link name="BR1">
        <visual>
            <origin xyz="0 0.0325 0" rpy="0.0 1.571 0.0"/>
            <geometry>
                <box size="0.0127 0.06541 0.0381"/>
            </geometry>
            <material name = "Purple">
                <color rgba="0.522 0 1 1.0"/>               
            </material>      
        </visual>
        <collision>
            <origin xyz="0 0.0325 0" rpy="0.0 1.571 0.0"/>
            <geometry>
                <box size="0.0127 0.06541 0.0381"/>
            </geometry>
        </collision>
        <inertial>
            <mass value="1"/>
            <inertia ixx="1.0" ixy="0.0" ixz="0.0" iyy="1.0" iyz="0.0" izz="1.0"/>
        </inertial>
    </link>
    <joint name="BRJ1" type="revolute">
        <axis xyz="1 0 0"/>
        <parent link="BR0"/>
        <child link="BR1"/>
        <origin rpy="0 0 0" xyz="0 0.028395 0"/>
        <limit effort="100" velocity="100" lower="-1.571" upper="1.571"/>
        <joint_properties damping="0.0" friction="0.0"/>
    </joint>

    <link name="BR2">
        <visual>
            <origin xyz="0 0.052 0" rpy="1.571 0 0"/>
            <geometry>
                <cylinder radius=".008" length="0.104"/>
            </geometry>
            <material name = "Purple">
                <color rgba="0.522 0 1 1.0"/>               
            </material>    
        </visual>
        <collision>
            <origin xyz="0 0.052 0" rpy="1.571 0 0"/>
            <geometry>
                <cylinder radius=".008" length="0.104"/>
            </geometry>
        </collision>
        <inertial>
            <mass value="1"/>
           <inertia ixx="1.0" ixy="0.0" ixz="0.0" iyy="1.0" iyz="0.0" izz="1.0"/>
        </inertial>
    </link>
    <joint name="BRJ2" type="revolute">
        <axis xyz="1 0 0"/>
        <parent link="BR1"/>
        <child link="BR2"/>
        <origin rpy="0 0 0" xyz="0 0.06 0"/>
        <limit effort="100" velocity="100" lower="-1.571" upper="-0.4"/>
        <joint_properties damping="0.0" friction="0.0"/>
    </joint>

        <link name="BRE">
        <inertial>
            <origin xyz="0.0 0.0 0.0" rpy="0.0 0.0 0.0"/>
            <mass value="0.5"/>
            <inertia ixx="1.0" ixy="0.0" ixz="0.0" iyy="1.0" iyz="0.0" izz="1.0"/>
        </inertial>
        <visual name="BRRubberEnd">
            <origin xyz="0.0 0.0 0.0" rpy="0.0 0.0 0.0"/>
            <geometry>
                <sphere radius="0.008"/>
            </geometry>
            <material name="White">
                <color rgba="1.0 1.0 1.0 1.0"/>
            </material>
        </visual>
        <collision>
            <origin xyz="0.0 0.0 0.0" rpy="0.0 0.0 0.0"/>
            <geometry>
                <sphere radius="0.008"/>
            </geometry>
        </collision>
    </link>
    <joint name="BREJ" type="fixed">
        <origin xyz="0.0 0.104 0.0" rpy="0.0 0.0 0.0"/>
        <parent link="BR2"/>
        <child link="BRE"/>
    </joint>

    <!-- Servo Weights -->
    <link name="Servo0">
        <inertial>
            <mass value="0.0134"/>
            <inertia ixx="0.0" ixy="0.0" ixz="0.0" iyy="0.0" iyz="0.0" izz="0.0"/>
        </inertial>
        <visual name="">
            <origin xyz="0.0 0.0 0.0" rpy="0.0 0.0 0.0"/>
            <geometry>
                <box size="0.0228 0.0122 0.0285"/>
            </geometry>
            <material name="Black">
                <color rgba="0.0 0.0 0.0 1.0"/>
            </material>
        </visual>
        <collision>
            <origin xyz="0.0 0.0 0.0" rpy="0.0 0.0 0.0"/>
            <geometry>
                <box size="0.0228 0.0122 0.0285"/>
            </geometry>
        </collision>
    </link>

    <joint name="S0J" type="fixed">
        <origin rpy="0.0 0.0 0.0" xyz="-0.034317 -0.048021 0"/>
        <parent link="SpiderBody"/>
        <child link="Servo0"/>
    </joint>


</robot>